Workbook

Sheet Instruções
B2: SOLICITAÇÃO DE ORÇAMENTO — IMPERMEABILIZAÇÃO
B3: Cliente: AZO INCORPORADORA | Obra: PENÍNSULA RJ - FASE A
B4: Base: planilha de quantitativo IMP-LO-121-PLA-R03 (emissão 07/07/2026, rev. R03). Quantidades de projeto — confirmar in loco.
B6: COMO PREENCHER
B7: 1. Preencha SOMENTE as células AMARELAS da aba "Proposta": dados da empresa, preço unitário de MATERIAL e de MÃO DE OBRA (R$/m²) e as perguntas de escopo.
B8: 2. Os preços são por m² de SISTEMA COMPLETO, conforme o código do projeto (todas as camadas descritas: primer, manta/membrana, tela de poliéster, banho de asfalto, camada separadora, antirraiz, XPS etc.), incluindo arremates, reforços em ralos, rodapés, juntas, meia-cana e teste de estanqueidade.
B9: 3. Os serviços complementares (regularização, proteção mecânica, drenagem) são cotados em separado, para que possamos comparar propostas que incluem ou não esses serviços. Se não executar algum, deixe em branco e marque "Não" na pergunta correspondente.
B10: 4. As quantidades, totais e a distribuição por pavimento são calculadas automaticamente — não altere. Caso discorde de alguma quantidade, informe no campo "Observações".
B11: 5. O Opcional Piscina (personalização de unidades) usa os MESMOS preços unitários do grupo 1/2 e é somado à parte; não entra no total base.
B13: ABAS
B14: Proposta — formulário a ser preenchido pelo fornecedor (16 sistemas + 5 complementares + opcional).
B15: Qtd por Pavimento — quantidades e valores distribuídos por pavimento e por bloco (calculado a partir da Memória).
... B20: LEGENDA: células amarelas = preenchimento do fornecedor | células cinza = totais calculados | laranja = opcional piscina

Sheet Proposta
A1: PROPOSTA — IMPERMEABILIZAÇÃO | AZO INCORPORADORA | PENÍNSULA RJ - FASE A
A3: Empresa:
A4: CNPJ:
A5: Contato / telefone / e-mail:
A6: Data da proposta:
A7: Validade da proposta (dias):
A8: Prazo de execução estimado:
A9: Condição de pagamento:
A11: Item | B11: Código | C11: Descrição do serviço | D11: Onde se aplica | E11: Un. | F11: Quantidade | G11: P. unit. material (R$/un) | H11: P. unit. mão de obra (R$/un) | I11: P. unit. total (R$/un) | J11: Total (R$)
A12: 1 | B12: SISTEMAS DE IMPERMEABILIZAÇÃO (preço por m² de sistema completo)
A13: 1.01 | B13: I20EL | C13: [Membranas acrílicas] Membrana de polímero acrílico sem cimento 2,0 kg/m² estruturada c/ tela de poliéster nos pontos críticos | D13: Banho, Banho Serviço, Lavabo, Comp. Lixo, Tubulação Emergente | E13: m² | F13: =SUMIFS('Memória por Ambiente'!$M$2:$M$296,'Memória por Ambiente'!$I$2:$I$296,B13,'Memória por Ambiente'!$B$2:$B$296,"Base") | I13: =G13+H13 | J13: =F13*I13
A14: 1.02 | B14: I30EL | C14: [Membranas acrílicas] Membrana de polímero acrílico sem cimento 3,0 kg/m² estruturada c/ tela de poliéster nos pontos críticos | D14: Terraço, Laje Impermeabilizada, Abas, Abas Terraços, Abas Floreiras | E14: m² | F14: =SUMIFS('Memória por Ambiente'!$M$2:$M$296,'Memória por Ambiente'!$I$2:$I$296,B14,'Memória por Ambiente'!$B$2:$B$296,"Base") | I14: =G14+H14 | J14: =F14*I14
A15: 1.03 | B15: I30 | C15: [Membranas acrílicas] Membrana acrílica 3,0 kg/m² estruturada c/ tela de poliéster nos pontos críticos | D15: Cobertura Dutos | E15: m² | F15: =SUMIFS('Memória por Ambiente'!$M$2:$M$296,'Memória por Ambiente'!$I$2:$I$296,B15,'Memória por Ambiente'!$B$2:$B$296,"Base") | I15: =G15+H15 | J15: =F15*I15
A16: 1.04 | B16: D2 | C16: [Membranas acrílicas] Membrana de polímero acrílico com cimento 2,0 kg/m² estruturada c/ tela de poliéster | D16: Parede Ducha | E16: m² | F16: =SUMIFS('Memória por Ambiente'!$M$2:$M$296,'Memória por Ambiente'!$I$2:$I$296,B16,'Memória por Ambiente'!$B$2:$B$296,"Base") | I16: =G16+H16 | J16: =F16*I16
A17: 1.05 | B17: C3 | C17: [Cimentícios] Argamassa polimérica rígida 3,0 kg/m² estruturada c/ tela de poliéster nos pontos críticos | D17: Terraço, Caixão Perdido | E17: m² | F17: =SUMIFS('Memória por Ambiente'!$M$2:$M$296,'Memória por Ambiente'!$I$2:$I$296,B17,'Memória por Ambiente'!$B$2:$B$296,"Base") | I17: =G17+H17 | J17: =F17*I17
A18: 1.06 | B18: C4 | C18: [Cimentícios] Argamassa polimérica rígida 4,0 kg/m² estruturada c/ tela de poliéster nos pontos críticos | D18: Barrado | E18: m² | F18: =SUMIFS('Memória por Ambiente'!$M$2:$M$296,'Memória por Ambiente'!$I$2:$I$296,B18,'Memória por Ambiente'!$B$2:$B$296,"Base") | I18: =G18+H18 | J18: =F18*I18
A19: 1.07 | B19: C3I20EL | C19: [Cimentícios] Argamassa polimérica rígida 3,0 kg/m² + membrana acrílica sem cimento 2,0 kg/m² c/ tela de poliéster | D19: Banho Master Semi-Elevado | E19: m² | F19: =SUMIFS('Memória por Ambiente'!$M$2:$M$296,'Memória por Ambiente'!$I$2:$I$296,B19,'Memória por Ambiente'!$B$2:$B$296,"Base") | I19: =G19+H19 | J19: =F19*I19
A20: 1.08 | B20: C4RQD3T | C20: [Cimentícios] Argamassa polimérica rígida alta resist. química 4,0 kg/m² + membrana acrílica c/ cimento 3,0 kg/m² totalmente estruturada | D20: Caixas de Pluvial / Esgoto | E20: m² | F20: =SUMIFS('Memória por Ambiente'!$M$2:$M$296,'Memória por Ambiente'!$I$2:$I$296,B20,'Memória por Ambiente'!$B$2:$B$296,"Base") | I20: =G20+H20 | J20: =F20*I20
A21: 1.09 | B21: M44A | C21: [Mantas asfálticas] Manta asfáltica tipo IV 4 mm (A) areia/areia aderida c/ asfalto oxidado 3,0 kg/m² + banho de asfalto 2,0 kg/m² + camada separadora | D21: Laje Impermeabilizada, Clausura, Escada Privativa, Acessos Privativos, Caixão Perdido | E21: m² | F21: =SUMIFS('Memória por Ambiente'!$M$2:$M$296,'Memória por Ambiente'!$I$2:$I$296,B21,'Memória por Ambiente'!$B$2:$B$296,"Base") | I21: =G21+H21 | J21: =F21*I21
A22: 1.10 | B22: M44AC | C22: [Mantas asfálticas] Sistema M44A + camada de amortecimento (argamassa 1:8 c/ emulsão asfáltica) | D22: Rampa de Veículos | E22: m² | F22: =SUMIFS('Memória por Ambiente'!$M$2:$M$296,'Memória por Ambiente'!$I$2:$I$296,B22,'Memória por Ambiente'!$B$2:$B$296,"Base") | I22: =G22+H22 | J22: =F22*I22
A23: 1.11 | B23: M44AD2 | C23: [Mantas asfálticas] Sistema M44A + membrana acrílica c/ cimento 2,0 kg/m² sob revestimento (anti-eflorescência) | D23: Terraço, Terraço Descoberto, Lazer, Vertedouro | E23: m² | F23: =SUMIFS('Memória por Ambiente'!$M$2:$M$296,'Memória por Ambiente'!$I$2:$I$296,B23,'Memória por Ambiente'!$B$2:$B$296,"Base") | I23: =G23+H23 | J23: =F23*I23
A24: 1.12 | B24: M34AM44AD2 | C24: [Mantas asfálticas] Dupla manta: tipo III 4 mm + tipo IV 4 mm aderidas c/ asfalto oxidado + banho de asfalto + membrana acrílica c/ cimento 2,0 kg/m² | D24: Riacho, Piscina Raia | E24: m² | F24: =SUMIFS('Memória por Ambiente'!$M$2:$M$296,'Memória por Ambiente'!$I$2:$I$296,B24,'Memória por Ambiente'!$B$2:$B$296,"Base") | I24: =G24+H24 | J24: =F24*I24
... A28: 1.16 | B28: JP30AR05 | C28: [Poliuretano] Sistema JP30A + pintura de proteção antirraiz 0,5 l/m² sobre a proteção mecânica | D28: Floreiras, Floreira | E28: m² | F28: =SUMIFS('Memória por Ambiente'!$M$2:$M$296,'Memória por Ambiente'!$I$2:$I$296,B28,'Memória por Ambiente'!$B$2:$B$296,"Base") | I28: =G28+H28 | J28: =F28*I28
I29: Subtotal 1 | J29: =SUM(J13:J28)
A31: 2 | B31: SERVIÇOS COMPLEMENTARES (cotar em separado — deixar em branco se não executa)
A32: 2.01 | B32: CP01 | C32: Regularização / acerto de superfície (argamassa cimento e areia 1:3 c/ aditivo) | D32: Base da maioria dos sistemas | E32: m² | F32: =SUMIFS('Memória por Ambiente'!$N$2:$N$296,'Memória por Ambiente'!$B$2:$B$296,"Base") | I32: =G32+H32 | J32: =F32*I32
A33: 2.02 | B33: CP02 | C33: Proteção mecânica horizontal (argamassa cimento e areia 1:3) | D33: Lajes, terraços, jardins, floreiras, caixões perdidos | E33: m² | F33: =SUMIFS('Memória por Ambiente'!$O$2:$O$296,'Memória por Ambiente'!$B$2:$B$296,"Base") | I33: =G33+H33 | J33: =F33*I33
A34: 2.03 | B34: CP03 | C34: Proteção mecânica vertical armada c/ tela plástica ou galvanizada | D34: Rodapés/paredes de sistemas com manta e jardins | E34: m² | F34: =SUMIFS('Memória por Ambiente'!$P$2:$P$296,'Memória por Ambiente'!$B$2:$B$296,"Base") | I34: =G34+H34 | J34: =F34*I34
A35: 2.04 | B35: CP04 | C35: Proteção mecânica armada em concreto fck 30 MPa c/ tela Q92 (rampas) | D35: Rampa de veículos (verificar se é da construtora) | E35: m² | F35: =SUMIFS('Memória por Ambiente'!$Q$2:$Q$296,'Memória por Ambiente'!$B$2:$B$296,"Base") | I35: =G35+H35 | J35: =F35*I35
A36: 2.05 | B36: CP05 | C36: Drenagem com geocomposto tipo Macdrain 2L FP (floreiras/jardins) | D36: Floreiras e jardins sobre laje | E36: m² | F36: =SUMIFS('Memória por Ambiente'!$R$2:$R$296,'Memória por Ambiente'!$B$2:$B$296,"Base") | I36: =G36+H36 | J36: =F36*I36
I37: Subtotal 2 | J37: =SUM(J32:J36)
C39: TOTAL BASE (1 + 2) | J39: =J29+J37
A41: 3 | B41: OPCIONAL — OPÇÃO DE PISCINA (personalização; usa os preços unitários acima; NÃO soma no total base)
A42: 3.01 | B42: M44A | C42: =C21 | D42: Opção de piscina (térreo e 2º pav.) | E42: m² | F42: =SUMIFS('Memória por Ambiente'!$M$2:$M$296,'Memória por Ambiente'!$I$2:$I$296,B42,'Memória por Ambiente'!$B$2:$B$296,"Opcional piscina") | G42: =G21 | H42: =H21 | I42: =I21 | J42: =F42*I42
A43: 3.02 | B43: M44AD2 | C43: =C23 | D43: Opção de piscina (térreo e 2º pav.) | E43: m² | F43: =SUMIFS('Memória por Ambiente'!$M$2:$M$296,'Memória por Ambiente'!$I$2:$I$296,B43,'Memória por Ambiente'!$B$2:$B$296,"Opcional piscina") | G43: =G23 | H43: =H23 | I43: =I23 | J43: =F43*I43
A44: 3.03 | B44: M34AM44AD2 | C44: =C24 | D44: Opção de piscina (térreo e 2º pav.) | E44: m² | F44: =SUMIFS('Memória por Ambiente'!$M$2:$M$296,'Memória por Ambiente'!$I$2:$I$296,B44,'Memória por Ambiente'!$B$2:$B$296,"Opcional piscina") | G44: =G24 | H44: =H24 | I44: =I24 | J44: =F44*I44
A45: 3.04 | B45: M44AR05 | C45: =C25 | D45: Opção de piscina (térreo e 2º pav.) | E45: m² | F45: =SUMIFS('Memória por Ambiente'!$M$2:$M$296,'Memória por Ambiente'!$I$2:$I$296,B45,'Memória por Ambiente'!$B$2:$B$296,"Opcional piscina") | G45: =G25 | H45: =H25 | I45: =I25 | J45: =F45*I45
A46: 3.05 | B46: CP01 | C46: =C32 | D46: Opção de piscina | E46: m² | F46: =SUMIFS('Memória por Ambiente'!$N$2:$N$296,'Memória por Ambiente'!$B$2:$B$296,"Opcional piscina") | G46: =G32 | H46: =H32 | I46: =I32 | J46: =F46*I46
A47: 3.06 | B47: CP02 | C47: =C33 | D47: Opção de piscina | E47: m² | F47: =SUMIFS('Memória por Ambiente'!$O$2:$O$296,'Memória por Ambiente'!$B$2:$B$296,"Opcional piscina") | G47: =G33 | H47: =H33 | I47: =I33 | J47: =F47*I47
A48: 3.07 | B48: CP03 | C48: =C34 | D48: Opção de piscina | E48: m² | F48: =SUMIFS('Memória por Ambiente'!$P$2:$P$296,'Memória por Ambiente'!$B$2:$B$296,"Opcional piscina") | G48: =G34 | H48: =H34 | I48: =I34 | J48: =F48*I48
...

Sheet Qtd por Pavimento
A1: Quantidades e valores por pavimento — grupo Base (sem opcional piscina). Valores = quantidade × preço unitário total da aba Proposta.
A3: QUANTIDADES (m²) POR PAVIMENTO
A4: Código | B4: Un. | C4: 1º Subsolo | D4: Térreo | E4: 1º Pavimento | F4: 2º Pavimento | G4: Cobertura | H4: Total
A5: I20EL | B5: m² | C5: =SUMIFS('Memória por Ambiente'!$M$2:$M$296,'Memória por Ambiente'!$C$2:$C$296,"1º Subsolo",'Memória por Ambiente'!$B$2:$B$296,"Base",'Memória por Ambiente'!$I$2:$I$296,$A5) | D5: =SUMIFS('Memória por Ambiente'!$M$2:$M$296,'Memória por Ambiente'!$C$2:$C$296,"Térreo",'Memória por Ambiente'!$B$2:$B$296,"Base",'Memória por Ambiente'!$I$2:$I$296,$A5) | E5: =SUMIFS('Memória por Ambiente'!$M$2:$M$296,'Memória por Ambiente'!$C$2:$C$296,"1º Pavimento",'Memória por Ambiente'!$B$2:$B$296,"Base",'Memória por Ambiente'!$I$2:$I$296,$A5) | F5: =SUMIFS('Memória por Ambiente'!$M$2:$M$296,'Memória por Ambiente'!$C$2:$C$296,"2º Pavimento",'Memória por Ambiente'!$B$2:$B$296,"Base",'Memória por Ambiente'!$I$2:$I$296,$A5) | G5: =SUMIFS('Memória por Ambiente'!$M$2:$M$296,'Memória por Ambiente'!$C$2:$C$296,"Cobertura",'Memória por Ambiente'!$B$2:$B$296,"Base",'Memória por Ambiente'!$I$2:$I$296,$A5) | H5: =SUM(C5:G5)
A6: I30EL | B6: m² | C6: =SUMIFS('Memória por Ambiente'!$M$2:$M$296,'Memória por Ambiente'!$C$2:$C$296,"1º Subsolo",'Memória por Ambiente'!$B$2:$B$296,"Base",'Memória por Ambiente'!$I$2:$I$296,$A6) | D6: =SUMIFS('Memória por Ambiente'!$M$2:$M$296,'Memória por Ambiente'!$C$2:$C$296,"Térreo",'Memória por Ambiente'!$B$2:$B$296,"Base",'Memória por Ambiente'!$I$2:$I$296,$A6) | E6: =SUMIFS('Memória por Ambiente'!$M$2:$M$296,'Memória por Ambiente'!$C$2:$C$296,"1º Pavimento",'Memória por Ambiente'!$B$2:$B$296,"Base",'Memória por Ambiente'!$I$2:$I$296,$A6) | F6: =SUMIFS('Memória por Ambiente'!$M$2:$M$296,'Memória por Ambiente'!$C$2:$C$296,"2º Pavimento",'Memória por Ambiente'!$B$2:$B$296,"Base",'Memória por Ambiente'!$I$2:$I$296,$A6) | G6: =SUMIFS('Memória por Ambiente'!$M$2:$M$296,'Memória por Ambiente'!$C$2:$C$296,"Cobertura",'Memória por Ambiente'!$B$2:$B$296,"Base",'Memória por Ambiente'!$I$2:$I$296,$A6) | H6: =SUM(C6:G6)
A7: I30 | B7: m² | C7: =SUMIFS('Memória por Ambiente'!$M$2:$M$296,'Memória por Ambiente'!$C$2:$C$296,"1º Subsolo",'Memória por Ambiente'!$B$2:$B$296,"Base",'Memória por Ambiente'!$I$2:$I$296,$A7) | D7: =SUMIFS('Memória por Ambiente'!$M$2:$M$296,'Memória por Ambiente'!$C$2:$C$296,"Térreo",'Memória por Ambiente'!$B$2:$B$296,"Base",'Memória por Ambiente'!$I$2:$I$296,$A7) | E7: =SUMIFS('Memória por Ambiente'!$M$2:$M$296,'Memória por Ambiente'!$C$2:$C$296,"1º Pavimento",'Memória por Ambiente'!$B$2:$B$296,"Base",'Memória por Ambiente'!$I$2:$I$296,$A7) | F7: =SUMIFS('Memória por Ambiente'!$M$2:$M$296,'Memória por Ambiente'!$C$2:$C$296,"2º Pavimento",'Memória por Ambiente'!$B$2:$B$296,"Base",'Memória por Ambiente'!$I$2:$I$296,$A7) | G7: =SUMIFS('Memória por Ambiente'!$M$2:$M$296,'Memória por Ambiente'!$C$2:$C$296,"Cobertura",'Memória por Ambiente'!$B$2:$B$296,"Base",'Memória por Ambiente'!$I$2:$I$296,$A7) | H7: =SUM(C7:G7)
A8: D2 | B8: m² | C8: =SUMIFS('Memória por Ambiente'!$M$2:$M$296,'Memória por Ambiente'!$C$2:$C$296,"1º Subsolo",'Memória por Ambiente'!$B$2:$B$296,"Base",'Memória por Ambiente'!$I$2:$I$296,$A8) | D8: =SUMIFS('Memória por Ambiente'!$M$2:$M$296,'Memória por Ambiente'!$C$2:$C$296,"Térreo",'Memória por Ambiente'!$B$2:$B$296,"Base",'Memória por Ambiente'!$I$2:$I$296,$A8) | E8: =SUMIFS('Memória por Ambiente'!$M$2:$M$296,'Memória por Ambiente'!$C$2:$C$296,"1º Pavimento",'Memória por Ambiente'!$B$2:$B$296,"Base",'Memória por Ambiente'!$I$2:$I$296,$A8) | F8: =SUMIFS('Memória por Ambiente'!$M$2:$M$296,'Memória por Ambiente'!$C$2:$C$296,"2º Pavimento",'Memória por Ambiente'!$B$2:$B$296,"Base",'Memória por Ambiente'!$I$2:$I$296,$A8) | G8: =SUMIFS('Memória por Ambiente'!$M$2:$M$296,'Memória por Ambiente'!$C$2:$C$296,"Cobertura",'Memória por Ambiente'!$B$2:$B$296,"Base",'Memória por Ambiente'!$I$2:$I$296,$A8) | H8: =SUM(C8:G8)
A9: C3 | B9: m² | C9: =SUMIFS('Memória por Ambiente'!$M$2:$M$296,'Memória por Ambiente'!$C$2:$C$296,"1º Subsolo",'Memória por Ambiente'!$B$2:$B$296,"Base",'Memória por Ambiente'!$I$2:$I$296,$A9) | D9: =SUMIFS('Memória por Ambiente'!$M$2:$M$296,'Memória por Ambiente'!$C$2:$C$296,"Térreo",'Memória por Ambiente'!$B$2:$B$296,"Base",'Memória por Ambiente'!$I$2:$I$296,$A9) | E9: =SUMIFS('Memória por Ambiente'!$M$2:$M$296,'Memória por Ambiente'!$C$2:$C$296,"1º Pavimento",'Memória por Ambiente'!$B$2:$B$296,"Base",'Memória por Ambiente'!$I$2:$I$296,$A9) | F9: =SUMIFS('Memória por Ambiente'!$M$2:$M$296,'Memória por Ambiente'!$C$2:$C$296,"2º Pavimento",'Memória por Ambiente'!$B$2:$B$296,"Base",'Memória por Ambiente'!$I$2:$I$296,$A9) | G9: =SUMIFS('Memória por Ambiente'!$M$2:$M$296,'Memória por Ambiente'!$C$2:$C$296,"Cobertura",'Memória por Ambiente'!$B$2:$B$296,"Base",'Memória por Ambiente'!$I$2:$I$296,$A9) | H9: =SUM(C9:G9)
A10: C4 | B10: m² | C10: =SUMIFS('Memória por Ambiente'!$M$2:$M$296,'Memória por Ambiente'!$C$2:$C$296,"1º Subsolo",'Memória por Ambiente'!$B$2:$B$296,"Base",'Memória por Ambiente'!$I$2:$I$296,$A10) | D10: =SUMIFS('Memória por Ambiente'!$M$2:$M$296,'Memória por Ambiente'!$C$2:$C$296,"Térreo",'Memória por Ambiente'!$B$2:$B$296,"Base",'Memória por Ambiente'!$I$2:$I$296,$A10) | E10: =SUMIFS('Memória por Ambiente'!$M$2:$M$296,'Memória por Ambiente'!$C$2:$C$296,"1º Pavimento",'Memória por Ambiente'!$B$2:$B$296,"Base",'Memória por Ambiente'!$I$2:$I$296,$A10) | F10: =SUMIFS('Memória por Ambiente'!$M$2:$M$296,'Memória por Ambiente'!$C$2:$C$296,"2º Pavimento",'Memória por Ambiente'!$B$2:$B$296,"Base",'Memória por Ambiente'!$I$2:$I$296,$A10) | G10: =SUMIFS('Memória por Ambiente'!$M$2:$M$296,'Memória por Ambiente'!$C$2:$C$296,"Cobertura",'Memória por Ambiente'!$B$2:$B$296,"Base",'Memória por Ambiente'!$I$2:$I$296,$A10) | H10: =SUM(C10:G10)
A11: C3I20EL | B11: m² | C11: =SUMIFS('Memória por Ambiente'!$M$2:$M$296,'Memória por Ambiente'!$C$2:$C$296,"1º Subsolo",'Memória por Ambiente'!$B$2:$B$296,"Base",'Memória por Ambiente'!$I$2:$I$296,$A11) | D11: =SUMIFS('Memória por Ambiente'!$M$2:$M$296,'Memória por Ambiente'!$C$2:$C$296,"Térreo",'Memória por Ambiente'!$B$2:$B$296,"Base",'Memória por Ambiente'!$I$2:$I$296,$A11) | E11: =SUMIFS('Memória por Ambiente'!$M$2:$M$296,'Memória por Ambiente'!$C$2:$C$296,"1º Pavimento",'Memória por Ambiente'!$B$2:$B$296,"Base",'Memória por Ambiente'!$I$2:$I$296,$A11) | F11: =SUMIFS('Memória por Ambiente'!$M$2:$M$296,'Memória por Ambiente'!$C$2:$C$296,"2º Pavimento",'Memória por Ambiente'!$B$2:$B$296,"Base",'Memória por Ambiente'!$I$2:$I$296,$A11) | G11: =SUMIFS('Memória por Ambiente'!$M$2:$M$296,'Memória por Ambiente'!$C$2:$C$296,"Cobertura",'Memória por Ambiente'!$B$2:$B$296,"Base",'Memória por Ambiente'!$I$2:$I$296,$A11) | H11: =SUM(C11:G11)
A12: C4RQD3T | B12: m² | C12: =SUMIFS('Memória por Ambiente'!$M$2:$M$296,'Memória por Ambiente'!$C$2:$C$296,"1º Subsolo",'Memória por Ambiente'!$B$2:$B$296,"Base",'Memória por Ambiente'!$I$2:$I$296,$A12) | D12: =SUMIFS('Memória por Ambiente'!$M$2:$M$296,'Memória por Ambiente'!$C$2:$C$296,"Térreo",'Memória por Ambiente'!$B$2:$B$296,"Base",'Memória por Ambiente'!$I$2:$I$296,$A12) | E12: =SUMIFS('Memória por Ambiente'!$M$2:$M$296,'Memória por Ambiente'!$C$2:$C$296,"1º Pavimento",'Memória por Ambiente'!$B$2:$B$296,"Base",'Memória por Ambiente'!$I$2:$I$296,$A12) | F12: =SUMIFS('Memória por Ambiente'!$M$2:$M$296,'Memória por Ambiente'!$C$2:$C$296,"2º Pavimento",'Memória por Ambiente'!$B$2:$B$296,"Base",'Memória por Ambiente'!$I$2:$I$296,$A12) | G12: =SUMIFS('Memória por Ambiente'!$M$2:$M$296,'Memória por Ambiente'!$C$2:$C$296,"Cobertura",'Memória por Ambiente'!$B$2:$B$296,"Base",'Memória por Ambiente'!$I$2:$I$296,$A12) | H12: =SUM(C12:G12)
A13: M44A | B13: m² | C13: =SUMIFS('Memória por Ambiente'!$M$2:$M$296,'Memória por Ambiente'!$C$2:$C$296,"1º Subsolo",'Memória por Ambiente'!$B$2:$B$296,"Base",'Memória por Ambiente'!$I$2:$I$296,$A13) | D13: =SUMIFS('Memória por Ambiente'!$M$2:$M$296,'Memória por Ambiente'!$C$2:$C$296,"Térreo",'Memória por Ambiente'!$B$2:$B$296,"Base",'Memória por Ambiente'!$I$2:$I$296,$A13) | E13: =SUMIFS('Memória por Ambiente'!$M$2:$M$296,'Memória por Ambiente'!$C$2:$C$296,"1º Pavimento",'Memória por Ambiente'!$B$2:$B$296,"Base",'Memória por Ambiente'!$I$2:$I$296,$A13) | F13: =SUMIFS('Memória por Ambiente'!$M$2:$M$296,'Memória por Ambiente'!$C$2:$C$296,"2º Pavimento",'Memória por Ambiente'!$B$2:$B$296,"Base",'Memória por Ambiente'!$I$2:$I$296,$A13) | G13: =SUMIFS('Memória por Ambiente'!$M$2:$M$296,'Memória por Ambiente'!$C$2:$C$296,"Cobertura",'Memória por Ambiente'!$B$2:$B$296,"Base",'Memória por Ambiente'!$I$2:$I$296,$A13) | H13: =SUM(C13:G13)
A14: M44AC | B14: m² | C14: =SUMIFS('Memória por Ambiente'!$M$2:$M$296,'Memória por Ambiente'!$C$2:$C$296,"1º Subsolo",'Memória por Ambiente'!$B$2:$B$296,"Base",'Memória por Ambiente'!$I$2:$I$296,$A14) | D14: =SUMIFS('Memória por Ambiente'!$M$2:$M$296,'Memória por Ambiente'!$C$2:$C$296,"Térreo",'Memória por Ambiente'!$B$2:$B$296,"Base",'Memória por Ambiente'!$I$2:$I$296,$A14) | E14: =SUMIFS('Memória por Ambiente'!$M$2:$M$296,'Memória por Ambiente'!$C$2:$C$296,"1º Pavimento",'Memória por Ambiente'!$B$2:$B$296,"Base",'Memória por Ambiente'!$I$2:$I$296,$A14) | F14: =SUMIFS('Memória por Ambiente'!$M$2:$M$296,'Memória por Ambiente'!$C$2:$C$296,"2º Pavimento",'Memória por Ambiente'!$B$2:$B$296,"Base",'Memória por Ambiente'!$I$2:$I$296,$A14) | G14: =SUMIFS('Memória por Ambiente'!$M$2:$M$296,'Memória por Ambiente'!$C$2:$C$296,"Cobertura",'Memória por Ambiente'!$B$2:$B$296,"Base",'Memória por Ambiente'!$I$2:$I$296,$A14) | H14: =SUM(C14:G14)
A15: M44AD2 | B15: m² | C15: =SUMIFS('Memória por Ambiente'!$M$2:$M$296,'Memória por Ambiente'!$C$2:$C$296,"1º Subsolo",'Memória por Ambiente'!$B$2:$B$296,"Base",'Memória por Ambiente'!$I$2:$I$296,$A15) | D15: =SUMIFS('Memória por Ambiente'!$M$2:$M$296,'Memória por Ambiente'!$C$2:$C$296,"Térreo",'Memória por Ambiente'!$B$2:$B$296,"Base",'Memória por Ambiente'!$I$2:$I$296,$A15) | E15: =SUMIFS('Memória por Ambiente'!$M$2:$M$296,'Memória por Ambiente'!$C$2:$C$296,"1º Pavimento",'Memória por Ambiente'!$B$2:$B$296,"Base",'Memória por Ambiente'!$I$2:$I$296,$A15) | F15: =SUMIFS('Memória por Ambiente'!$M$2:$M$296,'Memória por Ambiente'!$C$2:$C$296,"2º Pavimento",'Memória por Ambiente'!$B$2:$B$296,"Base",'Memória por Ambiente'!$I$2:$I$296,$A15) | G15: =SUMIFS('Memória por Ambiente'!$M$2:$M$296,'Memória por Ambiente'!$C$2:$C$296,"Cobertura",'Memória por Ambiente'!$B$2:$B$296,"Base",'Memória por Ambiente'!$I$2:$I$296,$A15) | H15: =SUM(C15:G15)
A16: M34AM44AD2 | B16: m² | C16: =SUMIFS('Memória por Ambiente'!$M$2:$M$296,'Memória por Ambiente'!$C$2:$C$296,"1º Subsolo",'Memória por Ambiente'!$B$2:$B$296,"Base",'Memória por Ambiente'!$I$2:$I$296,$A16) | D16: =SUMIFS('Memória por Ambiente'!$M$2:$M$296,'Memória por Ambiente'!$C$2:$C$296,"Térreo",'Memória por Ambiente'!$B$2:$B$296,"Base",'Memória por Ambiente'!$I$2:$I$296,$A16) | E16: =SUMIFS('Memória por Ambiente'!$M$2:$M$296,'Memória por Ambiente'!$C$2:$C$296,"1º Pavimento",'Memória por Ambiente'!$B$2:$B$296,"Base",'Memória por Ambiente'!$I$2:$I$296,$A16) | F16: =SUMIFS('Memória por Ambiente'!$M$2:$M$296,'Memória por Ambiente'!$C$2:$C$296,"2º Pavimento",'Memória por Ambiente'!$B$2:$B$296,"Base",'Memória por Ambiente'!$I$2:$I$296,$A16) | G16: =SUMIFS('Memória por Ambiente'!$M$2:$M$296,'Memória por Ambiente'!$C$2:$C$296,"Cobertura",'Memória por Ambiente'!$B$2:$B$296,"Base",'Memória por Ambiente'!$I$2:$I$296,$A16) | H16: =SUM(C16:G16)
... A20: JP30AR05 | B20: m² | C20: =SUMIFS('Memória por Ambiente'!$M$2:$M$296,'Memória por Ambiente'!$C$2:$C$296,"1º Subsolo",'Memória por Ambiente'!$B$2:$B$296,"Base",'Memória por Ambiente'!$I$2:$I$296,$A20) | D20: =SUMIFS('Memória por Ambiente'!$M$2:$M$296,'Memória por Ambiente'!$C$2:$C$296,"Térreo",'Memória por Ambiente'!$B$2:$B$296,"Base",'Memória por Ambiente'!$I$2:$I$296,$A20) | E20: =SUMIFS('Memória por Ambiente'!$M$2:$M$296,'Memória por Ambiente'!$C$2:$C$296,"1º Pavimento",'Memória por Ambiente'!$B$2:$B$296,"Base",'Memória por Ambiente'!$I$2:$I$296,$A20) | F20: =SUMIFS('Memória por Ambiente'!$M$2:$M$296,'Memória por Ambiente'!$C$2:$C$296,"2º Pavimento",'Memória por Ambiente'!$B$2:$B$296,"Base",'Memória por Ambiente'!$I$2:$I$296,$A20) | G20: =SUMIFS('Memória por Ambiente'!$M$2:$M$296,'Memória por Ambiente'!$C$2:$C$296,"Cobertura",'Memória por Ambiente'!$B$2:$B$296,"Base",'Memória por Ambiente'!$I$2:$I$296,$A20) | H20: =SUM(C20:G20)
A21: CP01 | B21: m² | C21: =SUMIFS('Memória por Ambiente'!$N$2:$N$296,'Memória por Ambiente'!$C$2:$C$296,"1º Subsolo",'Memória por Ambiente'!$B$2:$B$296,"Base") | D21: =SUMIFS('Memória por Ambiente'!$N$2:$N$296,'Memória por Ambiente'!$C$2:$C$296,"Térreo",'Memória por Ambiente'!$B$2:$B$296,"Base") | E21: =SUMIFS('Memória por Ambiente'!$N$2:$N$296,'Memória por Ambiente'!$C$2:$C$296,"1º Pavimento",'Memória por Ambiente'!$B$2:$B$296,"Base") | F21: =SUMIFS('Memória por Ambiente'!$N$2:$N$296,'Memória por Ambiente'!$C$2:$C$296,"2º Pavimento",'Memória por Ambiente'!$B$2:$B$296,"Base") | G21: =SUMIFS('Memória por Ambiente'!$N$2:$N$296,'Memória por Ambiente'!$C$2:$C$296,"Cobertura",'Memória por Ambiente'!$B$2:$B$296,"Base") | H21: =SUM(C21:G21)
A22: CP02 | B22: m² | C22: =SUMIFS('Memória por Ambiente'!$O$2:$O$296,'Memória por Ambiente'!$C$2:$C$296,"1º Subsolo",'Memória por Ambiente'!$B$2:$B$296,"Base") | D22: =SUMIFS('Memória por Ambiente'!$O$2:$O$296,'Memória por Ambiente'!$C$2:$C$296,"Térreo",'Memória por Ambiente'!$B$2:$B$296,"Base") | E22: =SUMIFS('Memória por Ambiente'!$O$2:$O$296,'Memória por Ambiente'!$C$2:$C$296,"1º Pavimento",'Memória por Ambiente'!$B$2:$B$296,"Base") | F22: =SUMIFS('Memória por Ambiente'!$O$2:$O$296,'Memória por Ambiente'!$C$2:$C$296,"2º Pavimento",'Memória por Ambiente'!$B$2:$B$296,"Base") | G22: =SUMIFS('Memória por Ambiente'!$O$2:$O$296,'Memória por Ambiente'!$C$2:$C$296,"Cobertura",'Memória por Ambiente'!$B$2:$B$296,"Base") | H22: =SUM(C22:G22)
A23: CP03 | B23: m² | C23: =SUMIFS('Memória por Ambiente'!$P$2:$P$296,'Memória por Ambiente'!$C$2:$C$296,"1º Subsolo",'Memória por Ambiente'!$B$2:$B$296,"Base") | D23: =SUMIFS('Memória por Ambiente'!$P$2:$P$296,'Memória por Ambiente'!$C$2:$C$296,"Térreo",'Memória por Ambiente'!$B$2:$B$296,"Base") | E23: =SUMIFS('Memória por Ambiente'!$P$2:$P$296,'Memória por Ambiente'!$C$2:$C$296,"1º Pavimento",'Memória por Ambiente'!$B$2:$B$296,"Base") | F23: =SUMIFS('Memória por Ambiente'!$P$2:$P$296,'Memória por Ambiente'!$C$2:$C$296,"2º Pavimento",'Memória por Ambiente'!$B$2:$B$296,"Base") | G23: =SUMIFS('Memória por Ambiente'!$P$2:$P$296,'Memória por Ambiente'!$C$2:$C$296,"Cobertura",'Memória por Ambiente'!$B$2:$B$296,"Base") | H23: =SUM(C23:G23)
A24: CP04 | B24: m² | C24: =SUMIFS('Memória por Ambiente'!$Q$2:$Q$296,'Memória por Ambiente'!$C$2:$C$296,"1º Subsolo",'Memória por Ambiente'!$B$2:$B$296,"Base") | D24: =SUMIFS('Memória por Ambiente'!$Q$2:$Q$296,'Memória por Ambiente'!$C$2:$C$296,"Térreo",'Memória por Ambiente'!$B$2:$B$296,"Base") | E24: =SUMIFS('Memória por Ambiente'!$Q$2:$Q$296,'Memória por Ambiente'!$C$2:$C$296,"1º Pavimento",'Memória por Ambiente'!$B$2:$B$296,"Base") | F24: =SUMIFS('Memória por Ambiente'!$Q$2:$Q$296,'Memória por Ambiente'!$C$2:$C$296,"2º Pavimento",'Memória por Ambiente'!$B$2:$B$296,"Base") | G24: =SUMIFS('Memória por Ambiente'!$Q$2:$Q$296,'Memória por Ambiente'!$C$2:$C$296,"Cobertura",'Memória por Ambiente'!$B$2:$B$296,"Base") | H24: =SUM(C24:G24)
A25: CP05 | B25: m² | C25: =SUMIFS('Memória por Ambiente'!$R$2:$R$296,'Memória por Ambiente'!$C$2:$C$296,"1º Subsolo",'Memória por Ambiente'!$B$2:$B$296,"Base") | D25: =SUMIFS('Memória por Ambiente'!$R$2:$R$296,'Memória por Ambiente'!$C$2:$C$296,"Térreo",'Memória por Ambiente'!$B$2:$B$296,"Base") | E25: =SUMIFS('Memória por Ambiente'!$R$2:$R$296,'Memória por Ambiente'!$C$2:$C$296,"1º Pavimento",'Memória por Ambiente'!$B$2:$B$296,"Base") | F25: =SUMIFS('Memória por Ambiente'!$R$2:$R$296,'Memória por Ambiente'!$C$2:$C$296,"2º Pavimento",'Memória por Ambiente'!$B$2:$B$296,"Base") | G25: =SUMIFS('Memória por Ambiente'!$R$2:$R$296,'Memória por Ambiente'!$C$2:$C$296,"Cobertura",'Memória por Ambiente'!$B$2:$B$296,"Base") | H25: =SUM(C25:G25)
A27: VALORES (R$) POR PAVIMENTO
A28: Código | B28: Un. | C28: 1º Subsolo | D28: Térreo | E28: 1º Pavimento | F28: 2º Pavimento | G28: Cobertura | H28: Total
A29: I20EL | B29: R$ | C29: =SUMIFS('Memória por Ambiente'!$M$2:$M$296,'Memória por Ambiente'!$C$2:$C$296,"1º Subsolo",'Memória por Ambiente'!$B$2:$B$296,"Base",'Memória por Ambiente'!$I$2:$I$296,$A29)*Proposta!$I$13 | D29: =SUMIFS('Memória por Ambiente'!$M$2:$M$296,'Memória por Ambiente'!$C$2:$C$296,"Térreo",'Memória por Ambiente'!$B$2:$B$296,"Base",'Memória por Ambiente'!$I$2:$I$296,$A29)*Proposta!$I$13 | E29: =SUMIFS('Memória por Ambiente'!$M$2:$M$296,'Memória por Ambiente'!$C$2:$C$296,"1º Pavimento",'Memória por Ambiente'!$B$2:$B$296,"Base",'Memória por Ambiente'!$I$2:$I$296,$A29)*Proposta!$I$13 | F29: =SUMIFS('Memória por Ambiente'!$M$2:$M$296,'Memória por Ambiente'!$C$2:$C$296,"2º Pavimento",'Memória por Ambiente'!$B$2:$B$296,"Base",'Memória por Ambiente'!$I$2:$I$296,$A29)*Proposta!$I$13 | G29: =SUMIFS('Memória por Ambiente'!$M$2:$M$296,'Memória por Ambiente'!$C$2:$C$296,"Cobertura",'Memória por Ambiente'!$B$2:$B$296,"Base",'Memória por Ambiente'!$I$2:$I$296,$A29)*Proposta!$I$13 | H29: =SUM(C29:G29)
A30: I30EL | B30: R$ | C30: =SUMIFS('Memória por Ambiente'!$M$2:$M$296,'Memória por Ambiente'!$C$2:$C$296,"1º Subsolo",'Memória por Ambiente'!$B$2:$B$296,"Base",'Memória por Ambiente'!$I$2:$I$296,$A30)*Proposta!$I$14 | D30: =SUMIFS('Memória por Ambiente'!$M$2:$M$296,'Memória por Ambiente'!$C$2:$C$296,"Térreo",'Memória por Ambiente'!$B$2:$B$296,"Base",'Memória por Ambiente'!$I$2:$I$296,$A30)*Proposta!$I$14 | E30: =SUMIFS('Memória por Ambiente'!$M$2:$M$296,'Memória por Ambiente'!$C$2:$C$296,"1º Pavimento",'Memória por Ambiente'!$B$2:$B$296,"Base",'Memória por Ambiente'!$I$2:$I$296,$A30)*Proposta!$I$14 | F30: =SUMIFS('Memória por Ambiente'!$M$2:$M$296,'Memória por Ambiente'!$C$2:$C$296,"2º Pavimento",'Memória por Ambiente'!$B$2:$B$296,"Base",'Memória por Ambiente'!$I$2:$I$296,$A30)*Proposta!$I$14 | G30: =SUMIFS('Memória por Ambiente'!$M$2:$M$296,'Memória por Ambiente'!$C$2:$C$296,"Cobertura",'Memória por Ambiente'!$B$2:$B$296,"Base",'Memória por Ambiente'!$I$2:$I$296,$A30)*Proposta!$I$14 | H30: =SUM(C30:G30)
A31: I30 | B31: R$ | C31: =SUMIFS('Memória por Ambiente'!$M$2:$M$296,'Memória por Ambiente'!$C$2:$C$296,"1º Subsolo",'Memória por Ambiente'!$B$2:$B$296,"Base",'Memória por Ambiente'!$I$2:$I$296,$A31)*Proposta!$I$15 | D31: =SUMIFS('Memória por Ambiente'!$M$2:$M$296,'Memória por Ambiente'!$C$2:$C$296,"Térreo",'Memória por Ambiente'!$B$2:$B$296,"Base",'Memória por Ambiente'!$I$2:$I$296,$A31)*Proposta!$I$15 | E31: =SUMIFS('Memória por Ambiente'!$M$2:$M$296,'Memória por Ambiente'!$C$2:$C$296,"1º Pavimento",'Memória por Ambiente'!$B$2:$B$296,"Base",'Memória por Ambiente'!$I$2:$I$296,$A31)*Proposta!$I$15 | F31: =SUMIFS('Memória por Ambiente'!$M$2:$M$296,'Memória por Ambiente'!$C$2:$C$296,"2º Pavimento",'Memória por Ambiente'!$B$2:$B$296,"Base",'Memória por Ambiente'!$I$2:$I$296,$A31)*Proposta!$I$15 | G31: =SUMIFS('Memória por Ambiente'!$M$2:$M$296,'Memória por Ambiente'!$C$2:$C$296,"Cobertura",'Memória por Ambiente'!$B$2:$B$296,"Base",'Memória por Ambiente'!$I$2:$I$296,$A31)*Proposta!$I$15 | H31: =SUM(C31:G31)
A32: D2 | B32: R$ | C32: =SUMIFS('Memória por Ambiente'!$M$2:$M$296,'Memória por Ambiente'!$C$2:$C$296,"1º Subsolo",'Memória por Ambiente'!$B$2:$B$296,"Base",'Memória por Ambiente'!$I$2:$I$296,$A32)*Proposta!$I$16 | D32: =SUMIFS('Memória por Ambiente'!$M$2:$M$296,'Memória por Ambiente'!$C$2:$C$296,"Térreo",'Memória por Ambiente'!$B$2:$B$296,"Base",'Memória por Ambiente'!$I$2:$I$296,$A32)*Proposta!$I$16 | E32: =SUMIFS('Memória por Ambiente'!$M$2:$M$296,'Memória por Ambiente'!$C$2:$C$296,"1º Pavimento",'Memória por Ambiente'!$B$2:$B$296,"Base",'Memória por Ambiente'!$I$2:$I$296,$A32)*Proposta!$I$16 | F32: =SUMIFS('Memória por Ambiente'!$M$2:$M$296,'Memória por Ambiente'!$C$2:$C$296,"2º Pavimento",'Memória por Ambiente'!$B$2:$B$296,"Base",'Memória por Ambiente'!$I$2:$I$296,$A32)*Proposta!$I$16 | G32: =SUMIFS('Memória por Ambiente'!$M$2:$M$296,'Memória por Ambiente'!$C$2:$C$296,"Cobertura",'Memória por Ambiente'!$B$2:$B$296,"Base",'Memória por Ambiente'!$I$2:$I$296,$A32)*Proposta!$I$16 | H32: =SUM(C32:G32)
A33: C3 | B33: R$ | C33: =SUMIFS('Memória por Ambiente'!$M$2:$M$296,'Memória por Ambiente'!$C$2:$C$296,"1º Subsolo",'Memória por Ambiente'!$B$2:$B$296,"Base",'Memória por Ambiente'!$I$2:$I$296,$A33)*Proposta!$I$17 | D33: =SUMIFS('Memória por Ambiente'!$M$2:$M$296,'Memória por Ambiente'!$C$2:$C$296,"Térreo",'Memória por Ambiente'!$B$2:$B$296,"Base",'Memória por Ambiente'!$I$2:$I$296,$A33)*Proposta!$I$17 | E33: =SUMIFS('Memória por Ambiente'!$M$2:$M$296,'Memória por Ambiente'!$C$2:$C$296,"1º Pavimento",'Memória por Ambiente'!$B$2:$B$296,"Base",'Memória por Ambiente'!$I$2:$I$296,$A33)*Proposta!$I$17 | F33: =SUMIFS('Memória por Ambiente'!$M$2:$M$296,'Memória por Ambiente'!$C$2:$C$296,"2º Pavimento",'Memória por Ambiente'!$B$2:$B$296,"Base",'Memória por Ambiente'!$I$2:$I$296,$A33)*Proposta!$I$17 | G33: =SUMIFS('Memória por Ambiente'!$M$2:$M$296,'Memória por Ambiente'!$C$2:$C$296,"Cobertura",'Memória por Ambiente'!$B$2:$B$296,"Base",'Memória por Ambiente'!$I$2:$I$296,$A33)*Proposta!$I$17 | H33: =SUM(C33:G33)
A34: C4 | B34: R$ | C34: =SUMIFS('Memória por Ambiente'!$M$2:$M$296,'Memória por Ambiente'!$C$2:$C$296,"1º Subsolo",'Memória por Ambiente'!$B$2:$B$296,"Base",'Memória por Ambiente'!$I$2:$I$296,$A34)*Proposta!$I$18 | D34: =SUMIFS('Memória por Ambiente'!$M$2:$M$296,'Memória por Ambiente'!$C$2:$C$296,"Térreo",'Memória por Ambiente'!$B$2:$B$296,"Base",'Memória por Ambiente'!$I$2:$I$296,$A34)*Proposta!$I$18 | E34: =SUMIFS('Memória por Ambiente'!$M$2:$M$296,'Memória por Ambiente'!$C$2:$C$296,"1º Pavimento",'Memória por Ambiente'!$B$2:$B$296,"Base",'Memória por Ambiente'!$I$2:$I$296,$A34)*Proposta!$I$18 | F34: =SUMIFS('Memória por Ambiente'!$M$2:$M$296,'Memória por Ambiente'!$C$2:$C$296,"2º Pavimento",'Memória por Ambiente'!$B$2:$B$296,"Base",'Memória por Ambiente'!$I$2:$I$296,$A34)*Proposta!$I$18 | G34: =SUMIFS('Memória por Ambiente'!$M$2:$M$296,'Memória por Ambiente'!$C$2:$C$296,"Cobertura",'Memória por Ambiente'!$B$2:$B$296,"Base",'Memória por Ambiente'!$I$2:$I$296,$A34)*Proposta!$I$18 | H34: =SUM(C34:G34)
A35: C3I20EL | B35: R$ | C35: =SUMIFS('Memória por Ambiente'!$M$2:$M$296,'Memória por Ambiente'!$C$2:$C$296,"1º Subsolo",'Memória por Ambiente'!$B$2:$B$296,"Base",'Memória por Ambiente'!$I$2:$I$296,$A35)*Proposta!$I$19 | D35: =SUMIFS('Memória por Ambiente'!$M$2:$M$296,'Memória por Ambiente'!$C$2:$C$296,"Térreo",'Memória por Ambiente'!$B$2:$B$296,"Base",'Memória por Ambiente'!$I$2:$I$296,$A35)*Proposta!$I$19 | E35: =SUMIFS('Memória por Ambiente'!$M$2:$M$296,'Memória por Ambiente'!$C$2:$C$296,"1º Pavimento",'Memória por Ambiente'!$B$2:$B$296,"Base",'Memória por Ambiente'!$I$2:$I$296,$A35)*Proposta!$I$19 | F35: =SUMIFS('Memória por Ambiente'!$M$2:$M$296,'Memória por Ambiente'!$C$2:$C$296,"2º Pavimento",'Memória por Ambiente'!$B$2:$B$296,"Base",'Memória por Ambiente'!$I$2:$I$296,$A35)*Proposta!$I$19 | G35: =SUMIFS('Memória por Ambiente'!$M$2:$M$296,'Memória por Ambiente'!$C$2:$C$296,"Cobertura",'Memória por Ambiente'!$B$2:$B$296,"Base",'Memória por Ambiente'!$I$2:$I$296,$A35)*Proposta!$I$19 | H35: =SUM(C35:G35)
A36: C4RQD3T | B36: R$ | C36: =SUMIFS('Memória por Ambiente'!$M$2:$M$296,'Memória por Ambiente'!$C$2:$C$296,"1º Subsolo",'Memória por Ambiente'!$B$2:$B$296,"Base",'Memória por Ambiente'!$I$2:$I$296,$A36)*Proposta!$I$20 | D36: =SUMIFS('Memória por Ambiente'!$M$2:$M$296,'Memória por Ambiente'!$C$2:$C$296,"Térreo",'Memória por Ambiente'!$B$2:$B$296,"Base",'Memória por Ambiente'!$I$2:$I$296,$A36)*Proposta!$I$20 | E36: =SUMIFS('Memória por Ambiente'!$M$2:$M$296,'Memória por Ambiente'!$C$2:$C$296,"1º Pavimento",'Memória por Ambiente'!$B$2:$B$296,"Base",'Memória por Ambiente'!$I$2:$I$296,$A36)*Proposta!$I$20 | F36: =SUMIFS('Memória por Ambiente'!$M$2:$M$296,'Memória por Ambiente'!$C$2:$C$296,"2º Pavimento",'Memória por Ambiente'!$B$2:$B$296,"Base",'Memória por Ambiente'!$I$2:$I$296,$A36)*Proposta!$I$20 | G36: =SUMIFS('Memória por Ambiente'!$M$2:$M$296,'Memória por Ambiente'!$C$2:$C$296,"Cobertura",'Memória por Ambiente'!$B$2:$B$296,"Base",'Memória por Ambiente'!$I$2:$I$296,$A36)*Proposta!$I$20 | H36: =SUM(C36:G36)
A37: M44A | B37: R$ | C37: =SUMIFS('Memória por Ambiente'!$M$2:$M$296,'Memória por Ambiente'!$C$2:$C$296,"1º Subsolo",'Memória por Ambiente'!$B$2:$B$296,"Base",'Memória por Ambiente'!$I$2:$I$296,$A37)*Proposta!$I$21 | D37: =SUMIFS('Memória por Ambiente'!$M$2:$M$296,'Memória por Ambiente'!$C$2:$C$296,"Térreo",'Memória por Ambiente'!$B$2:$B$296,"Base",'Memória por Ambiente'!$I$2:$I$296,$A37)*Proposta!$I$21 | E37: =SUMIFS('Memória por Ambiente'!$M$2:$M$296,'Memória por Ambiente'!$C$2:$C$296,"1º Pavimento",'Memória por Ambiente'!$B$2:$B$296,"Base",'Memória por Ambiente'!$I$2:$I$296,$A37)*Proposta!$I$21 | F37: =SUMIFS('Memória por Ambiente'!$M$2:$M$296,'Memória por Ambiente'!$C$2:$C$296,"2º Pavimento",'Memória por Ambiente'!$B$2:$B$296,"Base",'Memória por Ambiente'!$I$2:$I$296,$A37)*Proposta!$I$21 | G37: =SUMIFS('Memória por Ambiente'!$M$2:$M$296,'Memória por Ambiente'!$C$2:$C$296,"Cobertura",'Memória por Ambiente'!$B$2:$B$296,"Base",'Memória por Ambiente'!$I$2:$I$296,$A37)*Proposta!$I$21 | H37: =SUM(C37:G37)
A38: M44AC | B38: R$ | C38: =SUMIFS('Memória por Ambiente'!$M$2:$M$296,'Memória por Ambiente'!$C$2:$C$296,"1º Subsolo",'Memória por Ambiente'!$B$2:$B$296,"Base",'Memória por Ambiente'!$I$2:$I$296,$A38)*Proposta!$I$22 | D38: =SUMIFS('Memória por Ambiente'!$M$2:$M$296,'Memória por Ambiente'!$C$2:$C$296,"Térreo",'Memória por Ambiente'!$B$2:$B$296,"Base",'Memória por Ambiente'!$I$2:$I$296,$A38)*Proposta!$I$22 | E38: =SUMIFS('Memória por Ambiente'!$M$2:$M$296,'Memória por Ambiente'!$C$2:$C$296,"1º Pavimento",'Memória por Ambiente'!$B$2:$B$296,"Base",'Memória por Ambiente'!$I$2:$I$296,$A38)*Proposta!$I$22 | F38: =SUMIFS('Memória por Ambiente'!$M$2:$M$296,'Memória por Ambiente'!$C$2:$C$296,"2º Pavimento",'Memória por Ambiente'!$B$2:$B$296,"Base",'Memória por Ambiente'!$I$2:$I$296,$A38)*Proposta!$I$22 | G38: =SUMIFS('Memória por Ambiente'!$M$2:$M$296,'Memória por Ambiente'!$C$2:$C$296,"Cobertura",'Memória por Ambiente'!$B$2:$B$296,"Base",'Memória por Ambiente'!$I$2:$I$296,$A38)*Proposta!$I$22 | H38: =SUM(C38:G38)
A39: M44AD2 | B39: R$ | C39: =SUMIFS('Memória por Ambiente'!$M$2:$M$296,'Memória por Ambiente'!$C$2:$C$296,"1º Subsolo",'Memória por Ambiente'!$B$2:$B$296,"Base",'Memória por Ambiente'!$I$2:$I$296,$A39)*Proposta!$I$23 | D39: =SUMIFS('Memória por Ambiente'!$M$2:$M$296,'Memória por Ambiente'!$C$2:$C$296,"Térreo",'Memória por Ambiente'!$B$2:$B$296,"Base",'Memória por Ambiente'!$I$2:$I$296,$A39)*Proposta!$I$23 | E39: =SUMIFS('Memória por Ambiente'!$M$2:$M$296,'Memória por Ambiente'!$C$2:$C$296,"1º Pavimento",'Memória por Ambiente'!$B$2:$B$296,"Base",'Memória por Ambiente'!$I$2:$I$296,$A39)*Proposta!$I$23 | F39: =SUMIFS('Memória por Ambiente'!$M$2:$M$296,'Memória por Ambiente'!$C$2:$C$296,"2º Pavimento",'Memória por Ambiente'!$B$2:$B$296,"Base",'Memória por Ambiente'!$I$2:$I$296,$A39)*Proposta!$I$23 | G39: =SUMIFS('Memória por Ambiente'!$M$2:$M$296,'Memória por Ambiente'!$C$2:$C$296,"Cobertura",'Memória por Ambiente'!$B$2:$B$296,"Base",'Memória por Ambiente'!$I$2:$I$296,$A39)*Proposta!$I$23 | H39: =SUM(C39:G39)
A40: M34AM44AD2 | B40: R$ | C40: =SUMIFS('Memória por Ambiente'!$M$2:$M$296,'Memória por Ambiente'!$C$2:$C$296,"1º Subsolo",'Memória por Ambiente'!$B$2:$B$296,"Base",'Memória por Ambiente'!$I$2:$I$296,$A40)*Proposta!$I$24 | D40: =SUMIFS('Memória por Ambiente'!$M$2:$M$296,'Memória por Ambiente'!$C$2:$C$296,"Térreo",'Memória por Ambiente'!$B$2:$B$296,"Base",'Memória por Ambiente'!$I$2:$I$296,$A40)*Proposta!$I$24 | E40: =SUMIFS('Memória por Ambiente'!$M$2:$M$296,'Memória por Ambiente'!$C$2:$C$296,"1º Pavimento",'Memória por Ambiente'!$B$2:$B$296,"Base",'Memória por Ambiente'!$I$2:$I$296,$A40)*Proposta!$I$24 | F40: =SUMIFS('Memória por Ambiente'!$M$2:$M$296,'Memória por Ambiente'!$C$2:$C$296,"2º Pavimento",'Memória por Ambiente'!$B$2:$B$296,"Base",'Memória por Ambiente'!$I$2:$I$296,$A40)*Proposta!$I$24 | G40: =SUMIFS('Memória por Ambiente'!$M$2:$M$296,'Memória por Ambiente'!$C$2:$C$296,"Cobertura",'Memória por Ambiente'!$B$2:$B$296,"Base",'Memória por Ambiente'!$I$2:$I$296,$A40)*Proposta!$I$24 | H40: =SUM(C40:G40)
A41: M44AR05 | B41: R$ | C41: =SUMIFS('Memória por Ambiente'!$M$2:$M$296,'Memória por Ambiente'!$C$2:$C$296,"1º Subsolo",'Memória por Ambiente'!$B$2:$B$296,"Base",'Memória por Ambiente'!$I$2:$I$296,$A41)*Proposta!$I$25 | D41: =SUMIFS('Memória por Ambiente'!$M$2:$M$296,'Memória por Ambiente'!$C$2:$C$296,"Térreo",'Memória por Ambiente'!$B$2:$B$296,"Base",'Memória por Ambiente'!$I$2:$I$296,$A41)*Proposta!$I$25 | E41: =SUMIFS('Memória por Ambiente'!$M$2:$M$296,'Memória por Ambiente'!$C$2:$C$296,"1º Pavimento",'Memória por Ambiente'!$B$2:$B$296,"Base",'Memória por Ambiente'!$I$2:$I$296,$A41)*Proposta!$I$25 | F41: =SUMIFS('Memória por Ambiente'!$M$2:$M$296,'Memória por Ambiente'!$C$2:$C$296,"2º Pavimento",'Memória por Ambiente'!$B$2:$B$296,"Base",'Memória por Ambiente'!$I$2:$I$296,$A41)*Proposta!$I$25 | G41: =SUMIFS('Memória por Ambiente'!$M$2:$M$296,'Memória por Ambiente'!$C$2:$C$296,"Cobertura",'Memória por Ambiente'!$B$2:$B$296,"Base",'Memória por Ambiente'!$I$2:$I$296,$A41)*Proposta!$I$25 | H41: =SUM(C41:G41)
A42: M44AXPS | B42: R$ | C42: =SUMIFS('Memória por Ambiente'!$M$2:$M$296,'Memória por Ambiente'!$C$2:$C$296,"1º Subsolo",'Memória por Ambiente'!$B$2:$B$296,"Base",'Memória por Ambiente'!$I$2:$I$296,$A42)*Proposta!$I$26 | D42: =SUMIFS('Memória por Ambiente'!$M$2:$M$296,'Memória por Ambiente'!$C$2:$C$296,"Térreo",'Memória por Ambiente'!$B$2:$B$296,"Base",'Memória por Ambiente'!$I$2:$I$296,$A42)*Proposta!$I$26 | E42: =SUMIFS('Memória por Ambiente'!$M$2:$M$296,'Memória por Ambiente'!$C$2:$C$296,"1º Pavimento",'Memória por Ambiente'!$B$2:$B$296,"Base",'Memória por Ambiente'!$I$2:$I$296,$A42)*Proposta!$I$26 | F42: =SUMIFS('Memória por Ambiente'!$M$2:$M$296,'Memória por Ambiente'!$C$2:$C$296,"2º Pavimento",'Memória por Ambiente'!$B$2:$B$296,"Base",'Memória por Ambiente'!$I$2:$I$296,$A42)*Proposta!$I$26 | G42: =SUMIFS('Memória por Ambiente'!$M$2:$M$296,'Memória por Ambiente'!$C$2:$C$296,"Cobertura",'Memória por Ambiente'!$B$2:$B$296,"Base",'Memória por Ambiente'!$I$2:$I$296,$A42)*Proposta!$I$26 | H42: =SUM(C42:G42)
A43: JP30A | B43: R$ | C43: =SUMIFS('Memória por Ambiente'!$M$2:$M$296,'Memória por Ambiente'!$C$2:$C$296,"1º Subsolo",'Memória por Ambiente'!$B$2:$B$296,"Base",'Memória por Ambiente'!$I$2:$I$296,$A43)*Proposta!$I$27 | D43: =SUMIFS('Memória por Ambiente'!$M$2:$M$296,'Memória por Ambiente'!$C$2:$C$296,"Térreo",'Memória por Ambiente'!$B$2:$B$296,"Base",'Memória por Ambiente'!$I$2:$I$296,$A43)*Proposta!$I$27 | E43: =SUMIFS('Memória por Ambiente'!$M$2:$M$296,'Memória por Ambiente'!$C$2:$C$296,"1º Pavimento",'Memória por Ambiente'!$B$2:$B$296,"Base",'Memória por Ambiente'!$I$2:$I$296,$A43)*Proposta!$I$27 | F43: =SUMIFS('Memória por Ambiente'!$M$2:$M$296,'Memória por Ambiente'!$C$2:$C$296,"2º Pavimento",'Memória por Ambiente'!$B$2:$B$296,"Base",'Memória por Ambiente'!$I$2:$I$296,$A43)*Proposta!$I$27 | G43: =SUMIFS('Memória por Ambiente'!$M$2:$M$296,'Memória por Ambiente'!$C$2:$C$296,"Cobertura",'Memória por Ambiente'!$B$2:$B$296,"Base",'Memória por Ambiente'!$I$2:$I$296,$A43)*Proposta!$I$27 | H43: =SUM(C43:G43)
A44: JP30AR05 | B44: R$ | C44: =SUMIFS('Memória por Ambiente'!$M$2:$M$296,'Memória por Ambiente'!$C$2:$C$296,"1º Subsolo",'Memória por Ambiente'!$B$2:$B$296,"Base",'Memória por Ambiente'!$I$2:$I$296,$A44)*Proposta!$I$28 | D44: =SUMIFS('Memória por Ambiente'!$M$2:$M$296,'Memória por Ambiente'!$C$2:$C$296,"Térreo",'Memória por Ambiente'!$B$2:$B$296,"Base",'Memória por Ambiente'!$I$2:$I$296,$A44)*Proposta!$I$28 | E44: =SUMIFS('Memória por Ambiente'!$M$2:$M$296,'Memória por Ambiente'!$C$2:$C$296,"1º Pavimento",'Memória por Ambiente'!$B$2:$B$296,"Base",'Memória por Ambiente'!$I$2:$I$296,$A44)*Proposta!$I$28 | F44: =SUMIFS('Memória por Ambiente'!$M$2:$M$296,'Memória por Ambiente'!$C$2:$C$296,"2º Pavimento",'Memória por Ambiente'!$B$2:$B$296,"Base",'Memória por Ambiente'!$I$2:$I$296,$A44)*Proposta!$I$28 | G44: =SUMIFS('Memória por Ambiente'!$M$2:$M$296,'Memória por Ambiente'!$C$2:$C$296,"Cobertura",'Memória por Ambiente'!$B$2:$B$296,"Base",'Memória por Ambiente'!$I$2:$I$296,$A44)*Proposta!$I$28 | H44: =SUM(C44:G44)
A45: CP01 | B45: R$ | C45: =SUMIFS('Memória por Ambiente'!$N$2:$N$296,'Memória por Ambiente'!$C$2:$C$296,"1º Subsolo",'Memória por Ambiente'!$B$2:$B$296,"Base")*Proposta!$I$32 | D45: =SUMIFS('Memória por Ambiente'!$N$2:$N$296,'Memória por Ambiente'!$C$2:$C$296,"Térreo",'Memória por Ambiente'!$B$2:$B$296,"Base")*Proposta!$I$32 | E45: =SUMIFS('Memória por Ambiente'!$N$2:$N$296,'Memória por Ambiente'!$C$2:$C$296,"1º Pavimento",'Memória por Ambiente'!$B$2:$B$296,"Base")*Proposta!$I$32 | F45: =SUMIFS('Memória por Ambiente'!$N$2:$N$296,'Memória por Ambiente'!$C$2:$C$296,"2º Pavimento",'Memória por Ambiente'!$B$2:$B$296,"Base")*Proposta!$I$32 | G45: =SUMIFS('Memória por Ambiente'!$N$2:$N$296,'Memória por Ambiente'!$C$2:$C$296,"Cobertura",'Memória por Ambiente'!$B$2:$B$296,"Base")*Proposta!$I$32 | H45: =SUM(C45:G45)
...

Sheet Memória por Ambiente
A1: Nº | B1: Grupo | C1: Pavimento | D1: Bloco | E1: Folha | F1: Item | G1: Ambiente | H1: Ref. | I1: Código sistema | J1: Área horiz. local (m²) | K1: Área vert. local (m²) | L1: Repetições (pav × andar × torre) | M1: Área do sistema (m²) | N1: CP01 (m²) | O1: CP02 (m²) | P1: CP03 (m²) | Q1: CP04 (m²) | R1: CP05 (m²) | S1: Linha na planilha R03
A2: 1 | B2: Base | C2: 1º Subsolo | D2: A | E2: 105 | F2: 3.5.1 | G2: Banho 01 | H2: 1 | I2: I20EL | J2: 3.66 | K2: 8.14 | L2: 5 | M2: =(J2+K2)*L2 | N2: =11.8*L2 | S2: 10
A3: 2 | B3: Base | C3: 1º Subsolo | D3: A | E3: 105 | F3: 3.5.1 | G3: Banho 02 | H3: 2 | I3: I20EL | J3: 3.61 | K3: 8.13 | L3: 5 | M3: =(J3+K3)*L3 | N3: =11.74*L3 | S3: 18
A4: 3 | B4: Base | C4: 1º Subsolo | D4: A | E4: 105 | F4: 3.5.1 | G4: Banho Master Elevado | H4: 3 | I4: I20EL | J4: 6.51 | K4: 7.37 | L4: 2 | M4: =(J4+K4)*L4 | N4: =13.88*L4 | S4: 26
A5: 4 | B5: Base | C5: 1º Subsolo | D5: A | E5: 105 | F5: 3.5.2 | G5: Banho Master Semi-Elevado | H5: 4 | I5: C3I20EL | J5: 6.51 | K5: 7.37 | L5: 3 | M5: =(J5+K5)*L5 | N5: =13.88*L5 | S5: 35
A6: 5 | B6: Base | C6: 1º Subsolo | D6: A | E6: 105 | F6: 3.5.3 | G6: Terraço | H6: 5 | I6: C3 | J6: 18.4 | K6: 5.12 | L6: 5 | M6: =(J6+K6)*L6 | N6: =23.52*L6 | S6: 46
A7: 6 | B7: Base | C7: 1º Subsolo | D7: A | E7: 105 | F7: 3.5.4 | G7: Caixão Perdido | H7: 6 | I7: C3 | J7: 2.95 | K7: 10.46 | L7: 5 | M7: =(J7+K7)*L7 | N7: =13.41*L7 | O7: =13.41*L7 | S7: 54
A8: 7 | B8: Base | C8: 1º Subsolo | D8: A | E8: 105 | F8: 3.5.5 | G8: Floreiras | H8: 7 | I8: JP30AR05 | J8: 24 | K8: 106.75 | L8: 1 | M8: =(J8+K8)*L8 | N8: =130.75*L8 | O8: =130.75*L8 | R8: =24.0*L8 | S8: 65
A9: 8 | B9: Base | C9: 1º Subsolo | D9: A | E9: 105 | F9: 3.5.6 | G9: Escada 01 | H9: 8 | I9: M44A | J9: 5.15 | K9: 5.17 | L9: 1 | M9: =(J9+K9)*L9 | N9: =10.32*L9 | O9: =5.15*L9 | P9: =5.17*L9 | S9: 80
A10: 9 | B10: Base | C10: 1º Subsolo | D10: A | E10: 105 | F10: 3.5.6 | G10: Escada 02 | H10: 9 | I10: M44A | J10: 2.49 | K10: 2.99 | L10: 1 | M10: =(J10+K10)*L10 | N10: =5.48*L10 | O10: =2.49*L10 | P10: =2.99*L10 | S10: 94
A11: 10 | B11: Base | C11: 1º Subsolo | D11: A | E11: 105 | F11: 3.5.7 | G11: Rampa de Veículos | H11: 10 | I11: M44AC | J11: 82.37 | K11: 8.16 | L11: 1 | M11: =(J11+K11)*L11 | N11: =90.53*L11 | Q11: =82.37*L11 | S11: 109
A12: 11 | B12: Base | C12: 1º Subsolo | D12: A | E12: 105 | F12: 3.5.8 | G12: Barrado | H12: 11 | I12: C4 | J12: 0 | K12: 38.22 | L12: 1 | M12: =(J12+K12)*L12 | O12: =38.22*L12 | S12: 125
A13: 12 | B13: Base | C13: 1º Subsolo | D13: B | E13: 106 | F13: 3.6.1 | G13: Banho 01 | H13: 1 | I13: I20EL | J13: 3.66 | K13: 8.14 | L13: 4 | M13: =(J13+K13)*L13 | N13: =11.8*L13 | S13: 145
A14: 13 | B14: Base | C14: 1º Subsolo | D14: B | E14: 106 | F14: 3.6.1 | G14: Banho 02 | H14: 2 | I14: I20EL | J14: 3.61 | K14: 8.13 | L14: 4 | M14: =(J14+K14)*L14 | N14: =11.74*L14 | S14: 153
A15: 14 | B15: Base | C15: 1º Subsolo | D15: B | E15: 106 | F15: 3.6.1 | G15: Banho Master Elevado | H15: 3 | I15: I20EL | J15: 6.51 | K15: 7.37 | L15: 2 | M15: =(J15+K15)*L15 | N15: =13.88*L15 | S15: 161
A16: 15 | B16: Base | C16: 1º Subsolo | D16: B | E16: 106 | F16: 3.6.2 | G16: Banho Master Semi-Elevado | H16: 4 | I16: C3I20EL | J16: 6.51 | K16: 7.37 | L16: 2 | M16: =(J16+K16)*L16 | N16: =13.88*L16 | S16: 170
A17: 16 | B17: Base | C17: 1º Subsolo | D17: B | E17: 106 | F17: 3.6.3 | G17: Terraço | H17: 5 | I17: C3 | J17: 18.4 | K17: 5.12 | L17: 4 | M17: =(J17+K17)*L17 | N17: =23.52*L17 | S17: 181
A18: 17 | B18: Base | C18: 1º Subsolo | D18: B | E18: 106 | F18: 3.6.4 | G18: Caixão Perdido | H18: 6 | I18: C3 | J18: 2.95 | K18: 10.46 | L18: 4 | M18: =(J18+K18)*L18 | N18: =13.41*L18 | O18: =13.41*L18 | S18: 189
A19: 18 | B19: Base | C19: 1º Subsolo | D19: B | E19: 106 | F19: 3.6.5 | G19: Barrado | H19: 7 | I19: C4 | J19: 0 | K19: 35.45 | L19: 1 | M19: =(J19+K19)*L19 | O19: =35.45*L19 | S19: 200
A20: 19 | B20: Base | C20: 1º Subsolo | D20: B | E20: 106 | F20: 3.6.6 | G20: Floreiras | H20: 8 | I20: JP30AR05 | J20: 19.2 | K20: 85.4 | L20: 1 | M20: =(J20+K20)*L20 | N20: =104.6*L20 | O20: =104.6*L20 | R20: =19.2*L20 | S20: 209
A21: 20 | B21: Base | C21: 1º Subsolo | D21: C | E21: 107 | F21: 3.7.1 | G21: Banho 01 | H21: 1 | I21: I20EL | J21: 3.66 | K21: 8.14 | L21: 4 | M21: =(J21+K21)*L21 | N21: =11.8*L21 | S21: 235
A22: 21 | B22: Base | C22: 1º Subsolo | D22: C | E22: 107 | F22: 3.7.1 | G22: Banho 02 | H22: 2 | I22: I20EL | J22: 3.61 | K22: 8.13 | L22: 4 | M22: =(J22+K22)*L22 | N22: =11.74*L22 | S22: 243
A23: 22 | B23: Base | C23: 1º Subsolo | D23: C | E23: 107 | F23: 3.7.1 | G23: Banho Master Elevado | H23: 3 | I23: I20EL | J23: 6.51 | K23: 7.37 | L23: 3 | M23: =(J23+K23)*L23 | N23: =13.88*L23 | S23: 251
A24: 23 | B24: Base | C24: 1º Subsolo | D24: C | E24: 107 | F24: 3.7.2 | G24: Banho Master Semi-Elevado | H24: 4 | I24: C3I20EL | J24: 6.51 | K24: 7.37 | L24: 1 | M24: =(J24+K24)*L24 | N24: =13.88*L24 | S24: 260
A25: 24 | B25: Base | C25: 1º Subsolo | D25: C | E25: 107 | F25: 3.7.3 | G25: Terraço | H25: 5 | I25: C3 | J25: 18.4 | K25: 5.12 | L25: 4 | M25: =(J25+K25)*L25 | N25: =23.52*L25 | S25: 271
A26: 25 | B26: Base | C26: 1º Subsolo | D26: C | E26: 107 | F26: 3.7.4 | G26: Caixão Perdido | H26: 6 | I26: C3 | J26: 2.95 | K26: 10.46 | L26: 4 | M26: =(J26+K26)*L26 | N26: =13.41*L26 | O26: =13.41*L26 | S26: 279
A27: 26 | B27: Base | C27: 1º Subsolo | D27: C | E27: 107 | F27: 3.7.5 | G27: Barrado | H27: 7 | I27: C4 | J27: 0 | K27: 31.28 | L27: 1 | M27: =(J27+K27)*L27 | O27: =31.28*L27 | S27: 290
A28: 27 | B28: Base | C28: 1º Subsolo | D28: C | E28: 107 | F28: 3.7.6 | G28: Floreiras | H28: 8 | I28: JP30AR05 | J28: 19.2 | K28: 85.4 | L28: 1 | M28: =(J28+K28)*L28 | N28: =104.6*L28 | O28: =104.6*L28 | R28: =19.2*L28 | S28: 299
A29: 28 | B29: Base | C29: Térreo | D29: A | E29: 108 | F29: 3.8.1 | G29: Banho 01 | H29: 1 | I29: I20EL | J29: 3.66 | K29: 8.14 | L29: 5 | M29: =(J29+K29)*L29 | N29: =11.8*L29 | S29: 325
A30: 29 | B30: Base | C30: Térreo | D30: A | E30: 108 | F30: 3.8.1 | G30: Banho 02 | H30: 2 | I30: I20EL | J30: 3.61 | K30: 8.13 | L30: 5 | M30: =(J30+K30)*L30 | N30: =11.74*L30 | S30: 333
A31: 30 | B31: Base | C31: Térreo | D31: A | E31: 108 | F31: 3.8.1 | G31: Banho Master | H31: 3 | I31: I20EL | J31: 6.51 | K31: 7.37 | L31: 5 | M31: =(J31+K31)*L31 | N31: =13.88*L31 | S31: 341
A32: 31 | B32: Base | C32: Térreo | D32: A | E32: 108 | F32: 3.8.1 | G32: Banho Serviço | H32: 4 | I32: I20EL | J32: 2.59 | K32: 5.08 | L32: 5 | M32: =(J32+K32)*L32 | N32: =7.67*L32 | S32: 349
A33: 32 | B33: Base | C33: Térreo | D33: A | E33: 108 | F33: 3.8.1 | G33: Lavabo | H33: 5 | I33: I20EL | J33: 2.7 | K33: 1.84 | L33: 5 | M33: =(J33+K33)*L33 | N33: =4.54*L33 | S33: 357
A34: 33 | B34: Base | C34: Térreo | D34: A | E34: 108 | F34: 3.8.1 | G34: Área de Serviço | H34: 6 | I34: I20EL | J34: 3.92 | K34: 2.72 | L34: 5 | M34: =(J34+K34)*L34 | N34: =6.64*L34 | S34: 365
A35: 34 | B35: Base | C35: Térreo | D35: A | E35: 108 | F35: 3.8.1 | G35: Lixo | H35: 7 | I35: I20EL | J35: 0.78 | K35: 12.32 | L35: 1 | M35: =(J35+K35)*L35 | N35: =13.1*L35 | S35: 373
A36: 35 | B36: Base | C36: Térreo | D36: A | E36: 108 | F36: 3.8.1 | G36: Comp. Lixo | H36: 8 | I36: I20EL | J36: 1.09 | K36: 13.66 | L36: 2 | M36: =(J36+K36)*L36 | N36: =14.75*L36 | S36: 381
A37: 36 | B37: Base | C37: Térreo | D37: A | E37: 108 | F37: 3.8.1 | G37: Tubulação Emergente | H37: 9 | I37: I20EL | J37: 0.16 | K37: 0.08 | L37: 5 | M37: =(J37+K37)*L37 | N37: =0.24*L37 | S37: 389
A38: 37 | B38: Base | C38: Térreo | D38: A | E38: 108 | F38: 3.8.1 | G38: W.C. Portaria | H38: 10 | I38: I20EL | J38: 4.72 | K38: 2.49 | L38: 1 | M38: =(J38+K38)*L38 | N38: =7.21*L38 | S38: 397
A39: 38 | B39: Base | C39: Térreo | D39: A | E39: 108 | F39: 3.8.2 | G39: Shaft | H39: 11 | I39: I20EL | J39: 0.51 | K39: 0.65 | L39: 5 | M39: =(J39+K39)*L39 | N39: =1.16*L39 | O39: =1.16*L39 | S39: 405
A40: 39 | B40: Base | C40: Térreo | D40: A | E40: 108 | F40: 3.8.3 | G40: Caixas de Pluvial / Esgoto | H40: 12 | I40: C4RQD3T | J40: 10.4 | K40: 54.3 | L40: 1 | M40: =(J40+K40)*L40 | N40: =64.7*L40 | O40: =64.7*L40 | S40: 416
...

Sheet Especificação dos Sistemas
A1: Código | B1: Família | C1: Especificação completa (conforme projeto)
A2: I20EL | B2: Membranas acrílicas | C2: membrana de polímero acrílico sem cimento (2,0 kg/m²) com resistência à alcalinidade estruturada com tela de poliéster nos pontos críticos - REF. SIKA BAUCRYL; MC DF9; ICOPER HP; PROCRYL IMPER;
A3: I30EL | B3: Membranas acrílicas | C3: membrana de polímero acrílico sem cimento (3,0 kg/m²) com resistência à alcalinidade estruturada com tela de poliéster nos pontos críticos - REF. SIKA BAUCRYL; MC DF9; ICOPER HP; PROCRYL IMPER;
A4: I30 | B4: Membranas acrílicas | C4: membrana acrílica estruturada com tela de poliéster nos pontos críticos (3,0 kg/m²)
A5: D2 | B5: Membranas acrílicas | C5: membrana de polímero acrílico com cimento estruturada com tela de poliéster nos pontos críticos (2,0 kg/m²)
A6: C3 | B6: Cimentícios | C6: argamassa polimérica rígida estruturada com tela de poliéster nos pontos críticos (3,0 kg/m²)
A7: C4 | B7: Cimentícios | C7: argamassa polimérica rígida estruturada com tela de poliéster nos pontos críticos (4,0 kg/m²)
A8: C3I20EL | B8: Cimentícios | C8: argamassa polimérica rígida (3,0 kg/m²) + membrana de polímero acrílico sem cimento (2,0 kg/m²) com resistência à alcalinidade estruturada com tela de poliéster nos pontos críticos - REF. SIKA BAUCRYL; MC DF9; ICOPER HP; PROCRYL IMPER;
A9: C4RQD3T | B9: Cimentícios | C9: argamassa polimérica rígida com alta resistência química e estruturada com tela de poliéster nos pontos críticos (4,0 kg/m²) + membrana de polímero acrílico com cimento totalmente estruturada com tela de poliéster (3,0 kg/m²) -
A10: M44A | B10: Mantas asfálticas | C10: manta asfáltica tipo IV 4mm A com acabamento areia/areia aderida com asfalto oxidado (3,0 kg/m²) + banho de asfalto oxidado (2,0 kg/m²)
A11: M44AC | B11: Mantas asfálticas | C11: manta asfáltica tipo IV 4mm A com acabamento areia/areia aderida com asfalto oxidado (3,0 kg/m²) + banho de asfalto oxidado (2,0 kg/m²) + camada de amortecimento
A12: M44AD2 | B12: Mantas asfálticas | C12: manta asfáltica tipo IV 4mm A com acabamento areia/areia aderida com asfalto oxidado (3,0 kg/m²) + banho de asfalto oxidado (2,0 kg/m²) + membrana de polímero acrílico com cimento sob revestimento para combater eflorescência (2,0 kg/m²)
... A17: JP30AR05 | B17: Poliuretano | C17: primer à base de resina epóxi + membrana à base de poliuretano (3,0 kg/m²) estruturada nos pontos críticos e aspersão de agregado de quartzo # 8 - 14 (1,5 kg/m²) na última camada + pintura de proteção antirraiz sobre a proteção mecânica (0,5 l/m²)

Sheet Pendências
A1: # | B1: Linha(s) na R03 | C1: Ambiente / local | D1: Problema | E1: Impacto | F1: Tratamento neste resumo
A2: 1 | B2: 640, 656, 672, 688, 704, 720, 757, 1085, 1101, 1117, 1133, 1167, 1585, 1601, 1617, 1633, 1649, 1665, 1699, 2018, 2034, 2279, 2528, 2699, 2919, 3124 | C2: Proteção mecânica vertical (jardins, terraços) | D2: Custo total (coluna M) multiplica a área da linha de BAIXO (tela), que é vazia: =K641*L640. | E2: Com preço preenchido, o custo da proteção vertical sairia R$ 0. | F2: Não afeta quantidades; corrigir na planilha de origem.
A3: 2 | B3: 40, 175, 265, 3361, 3363, 3364, 3516, 3518, 3519, 3671, 3673, 3674 | C3: Tela de poliéster / itens diversos | D3: Custo total digitado como 0 (valor fixo) em vez de fórmula. | E3: Com preço preenchido, o custo dessas linhas sairia R$ 0. | F3: Não afeta quantidades; corrigir na planilha de origem.
A4: 3 | B4: 45, 180, 270 | C4: Totais do sistema C3I20EL (subsolos) | D4: Fórmula soma células de cabeçalho/linhas de outros ambientes (ex.: =K7+K19+K31+K43). Hoje dá o valor certo por coincidência. | E4: Frágil: quebra se linhas forem inseridas. | F4: Totais refeitos por SUMIFS a partir da Memória.
A5: 4 | B5: todas | C5: Estrutura geral | D5: Totais por sistema/pavimento montados manualmente, célula a célula (96 subtotais). | E5: Alto risco de erro em revisões futuras. | F5: Totais refeitos por SUMIFS; conferidos com a R03 (batem, exceto proteção mecânica acima).
